Workbook

Sheet Action Items
A1: AI-# | B1: Meeting Source | C1: Description | D1: Owner | E1: Due Date | F1: Status | G1: Priority | H1: Notes | I1: Days Since Assigned
A2: AI-001 | B2: OAC | C2: Submit revised foundation drawings to structural engineer for review | D2: David Chen | E2: 46188 | F2: In Progress | G2: High | H2: Awaiting feedback from engineer; follow up Thursday | I2: =IF(E2="","",TODAY()-E2)
A3: AI-002 | B3: Owner Mtg | C3: Obtain city building permit revision for south elevation change order | D3: Maria Santos | E3: 46198 | F3: Open | G3: Critical | H3: Permit fees approved; application ready to submit | I3: =IF(E3="","",TODAY()-E3)
A4: AI-003 | B4: Field Walk | C4: Resolve water intrusion at SW corner of basement — waterproofing detail missing | D4: Tom Bradley | E4: 46178 | F4: Overdue | G4: Critical | H4: Subcontractor to provide repair quote by EOD | I4: =IF(E4="","",TODAY()-E4)
A5: AI-004 | B5: Design Review | C5: Update MEP coordination drawings to reflect relocated ductwork in riser B | D5: Lisa Nguyen | E5: 46204 | F5: Open | G5: Medium | H5: Structural clash identified; BIM coordination in progress | I5: =IF(E5="","",TODAY()-E5)
A6: AI-005 | B6: Subcontractor Mtg | C6: Confirm steel delivery schedule for structural frame — verify mill lead times | D6: Kevin O'Brien | E6: 46183 | F6: Completed | G6: High | H6: Delivery confirmed for June 12; updated schedule distributed | I6: =IF(E6="","",TODAY()-E6)
A7: AI-006 | B7: Internal | C7: Approve glazing mock-up panel and sign off for production | D7: Emily Park | E7: 46176 | F7: In Progress | G7: High | H7: Coordinating with design team | I7: =IF(E7="","",TODAY()-E7)
A8: AI-007 | B8: Field Walk | C8: Coordinate glazing installation schedule with owner | D8: Maria Santos | E8: 46179 | F8: Completed | G8: High | H8: Needs follow-up this week | I8: =IF(E8="","",TODAY()-E8)
A9: AI-008 | B9: Owner Mtg | C9: Prepare HVAC change order documentation for engineer approval | D9: Emily Park | E9: 46126 | F9: Deferred | G9: Medium | H9: In progress - awaiting update | I9: =IF(E9="","",TODAY()-E9)
A10: AI-009 | B10: Design Review | C10: Conduct plumbing pre-installation meeting with consultant team | D10: Carlos Rivera | E10: 46129 | F10: Open | G10: Critical | H10: Waiting on external vendor | I10: =IF(E10="","",TODAY()-E10)
A11: AI-010 | B11: OAC | C11: Coordinate architectural installation schedule with city building dept | D11: Kevin O'Brien | E11: 46130 | F11: Overdue | G11: Low | H11: Needs follow-up this week | I11: =IF(E11="","",TODAY()-E11)
A12: AI-011 | B12: Design Review | C12: Verify architectural shop drawings against contract specifications | D12: Sarah Miller | E12: 46151 | F12: In Progress | G12: Low | H12: Waiting on external vendor | I12: =IF(E12="","",TODAY()-E12)
A13: AI-012 | B13: Field Walk | C13: Approve civil mock-up panel and sign off for production | D13: Jake Thompson | E13: 46130 | F13: Open | G13: High | H13: In progress - awaiting update | I13: =IF(E13="","",TODAY()-E13)
... A24: AI-023 | B24: Design Review | C24: Approve steel mock-up panel and sign off for production | D24: Rachel Kim | E24: 46174 | F24: Overdue | G24: Low | H24: Escalate if not resolved by Friday | I24: =IF(E24="","",TODAY()-E24)
A25: AI-024 | B25: Subcontractor Mtg | C25: Deliver architectural O&M manuals and training documentation | D25: Jake Thompson | E25: 46157 | F25: Deferred | G25: Low | I25: =IF(E25="","",TODAY()-E25)
A26: AI-025 | B26: Owner Mtg | C26: Expedite fire protection material submittal for owner approval | D26: Emily Park | E26: 46157 | F26: Deferred | G26: Medium | H26: In progress - awaiting update | I26: =IF(E26="","",TODAY()-E26)
A27: AI-026 | B27: Subcontractor Mtg | C27: Confirm steel equipment lead times and update procurement | D27: Emily Park | E27: 46148 | F27: In Progress | G27: High | H27: Subcontractor to provide ETA | I27: =IF(E27="","",TODAY()-E27)
A28: AI-027 | B28: Field Walk | C28: Verify plumbing shop drawings against contract specifications | D28: David Chen | E28: 46134 | F28: In Progress | G28: High | H28: Escalate if not resolved by Friday | I28: =IF(E28="","",TODAY()-E28)
A29: AI-028 | B29: OAC | C29: Submit revised curtain wall drawings for architect review | D29: Kevin O'Brien | E29: 46139 | F29: In Progress | G29: Medium | H29: Documentation filed pending review | I29: =IF(E29="","",TODAY()-E29)
A30: AI-029 | B30: Design Review | C30: Submit revised electrical drawings for architect review | D30: Rachel Kim | E30: 46135 | F30: Open | G30: Critical | H30: On track for deadline | I30: =IF(E30="","",TODAY()-E30)
A31: AI-030 | B31: Subcontractor Mtg | C31: Deliver curtain wall O&M manuals and training documentation | D31: David Chen | E31: 46145 | F31: Deferred | G31: High | H31: Subcontractor to provide ETA | I31: =IF(E31="","",TODAY()-E31)
A32: AI-031 | B32: Owner Mtg | C32: Coordinate roofing installation schedule with city building dept | D32: Kevin O'Brien | E32: 46138 | F32: Completed | G32: High | H32: Subcontractor to provide ETA | I32: =IF(E32="","",TODAY()-E32)
A33: AI-032 | B33: Design Review | C33: Prepare HVAC change order documentation for subcontractor approval | D33: Sarah Miller | E33: 46128 | F33: Overdue | G33: Low | H33: In progress - awaiting update | I33: =IF(E33="","",TODAY()-E33)
A34: AI-033 | B34: Internal | C34: Confirm fire protection equipment lead times and update procurement | D34: Jake Thompson | E34: 46171 | F34: In Progress | G34: High | H34: Coordinating with design team | I34: =IF(E34="","",TODAY()-E34)
A35: AI-034 | B35: Owner Mtg | C35: Expedite concrete material submittal for city building dept approval | D35: Tom Bradley | E35: 46154 | F35: Open | G35: High | H35: Documentation filed pending review | I35: =IF(E35="","",TODAY()-E35)
A36: AI-035 | B36: Internal | C36: Resolve fire protection RFI submitted by engineer | D36: David Chen | E36: 46142 | F36: Deferred | G36: Medium | H36: Needs follow-up this week | I36: =IF(E36="","",TODAY()-E36)
A37: AI-036 | B37: Internal | C37: Deliver steel O&M manuals and training documentation | D37: Tom Bradley | E37: 46133 | F37: Open | G37: High | H37: On track for deadline | I37: =IF(E37="","",TODAY()-E37)
A38: AI-037 | B38: Field Walk | C38: Resolve millwork RFI submitted by consultant | D38: Sarah Miller | E38: 46177 | F38: Deferred | G38: Critical | I38: =IF(E38="","",TODAY()-E38)
A39: AI-038 | B39: Field Walk | C39: Distribute fire protection meeting minutes and track action items | D39: Sarah Miller | E39: 46171 | F39: Open | G39: Medium | H39: Documentation filed pending review | I39: =IF(E39="","",TODAY()-E39)
A40: AI-039 | B40: Design Review | C40: Deliver structural O&M manuals and training documentation | D40: Rachel Kim | E40: 46155 | F40: Overdue | G40: High | H40: Escalate if not resolved by Friday | I40: =IF(E40="","",TODAY()-E40)
A41: AI-040 | B41: Design Review | C41: Coordinate glazing installation schedule with engineer | D41: Lisa Nguyen | E41: 46167 | F41: Deferred | G41: High | H41: Escalate if not resolved by Friday | I41: =IF(E41="","",TODAY()-E41)
A42: AI-041 | B42: OAC | C42: Issue MEP notice to proceed for owner scope | D42: Carlos Rivera | E42: 46173 | F42: Open | G42: Critical | H42: Needs follow-up this week | I42: =IF(E42="","",TODAY()-E42)
A43: AI-042 | B43: Internal | C43: Distribute roofing meeting minutes and track action items | D43: Maria Santos | E43: 46125 | F43: Completed | G43: Critical | H43: Coordinating with design team | I43: =IF(E43="","",TODAY()-E43)
A44: AI-043 | B44: Owner Mtg | C44: Flag architectural concealed conditions discovered during architect | D44: David Chen | E44: 46168 | F44: Overdue | G44: Low | I44: =IF(E44="","",TODAY()-E44)
A45: AI-044 | B45: Internal | C45: Expedite architectural material submittal for engineer approval | D45: Emily Park | E45: 46142 | F45: Deferred | G45: High | H45: Budget impact under review | I45: =IF(E45="","",TODAY()-E45)
A46: AI-045 | B46: Subcontractor Mtg | C46: Review architectural subcontractor proposal and negotiate terms | D46: Emily Park | E46: 46156 | F46: Completed | G46: High | H46: Needs follow-up this week | I46: =IF(E46="","",TODAY()-E46)
A47: AI-046 | B47: Field Walk | C47: Prepare electrical change order documentation for GC approval | D47: Tom Bradley | E47: 46140 | F47: Completed | G47: Medium | H47: Documentation filed pending review | I47: =IF(E47="","",TODAY()-E47)
A48: AI-047 | B48: Design Review | C48: Deliver electrical O&M manuals and training documentation | D48: Maria Santos | E48: 46157 | F48: Overdue | G48: Medium | H48: Escalate if not resolved by Friday | I48: =IF(E48="","",TODAY()-E48)
A49: AI-048 | B49: Design Review | C49: Approve roofing mock-up panel and sign off for production | D49: Maria Santos | E49: 46141 | F49: In Progress | G49: Medium | H49: Subcontractor to provide ETA | I49: =IF(E49="","",TODAY()-E49)
A50: AI-049 | B50: OAC | C50: Verify fire protection layout on site before city building dept commences | D50: Jake Thompson | E50: 46161 | F50: Open | G50: Medium | I50: =IF(E50="","",TODAY()-E50)
...

Sheet Summary
A1: Metric | B1: Category | C1: Count
A2: By Status
B3: Open | C3: =COUNTIF('Action Items'!F:F,B3)
B4: In Progress | C4: =COUNTIF('Action Items'!F:F,B4)
B5: Completed | C5: =COUNTIF('Action Items'!F:F,B5)
B6: Overdue | C6: =COUNTIF('Action Items'!F:F,B6)
B7: Deferred | C7: =COUNTIF('Action Items'!F:F,B7)
B8: Total | C8: =SUM(C3:C7)
A10: By Priority
B11: Low | C11: =COUNTIF('Action Items'!G:G,B11)
B12: Medium | C12: =COUNTIF('Action Items'!G:G,B12)
B13: High | C13: =COUNTIF('Action Items'!G:G,B13)
B14: Critical | C14: =COUNTIF('Action Items'!G:G,B14)
B15: Total | C15: =SUM(C11:C14)
A17: By Owner
B18: Jake Thompson | C18: =COUNTIF('Action Items'!D:D,B18)
B19: Maria Santos | C19: =COUNTIF('Action Items'!D:D,B19)
B20: David Chen | C20: =COUNTIF('Action Items'!D:D,B20)
B21: Sarah Miller | C21: =COUNTIF('Action Items'!D:D,B21)
B22: Tom Bradley | C22: =COUNTIF('Action Items'!D:D,B22)
B23: Lisa Nguyen | C23: =COUNTIF('Action Items'!D:D,B23)
B24: Kevin O'Brien | C24: =COUNTIF('Action Items'!D:D,B24)
B25: Rachel Kim | C25: =COUNTIF('Action Items'!D:D,B25)
B26: Carlos Rivera | C26: =COUNTIF('Action Items'!D:D,B26)
B27: Emily Park | C27: =COUNTIF('Action Items'!D:D,B27)
B28: Total | C28: =SUM(C18:C27)
