Workbook

Sheet Punch List
A1: Item # | B1: Location | C1: Trade | D1: Description | E1: Priority | F1: Assignee | G1: Date Identified | H1: Target Date | I1: Days Open | J1: Status | K1: Notes
A2: PL-001 | B2: Storage | C2: HVAC | D2: Toilet flange not secured to floor | E2: Medium | F2: M. Patel | G2: 46040 | H2: 46064 | I2: =IF(G2="","",TODAY()-G2) | J2: Ready for Review | K2: Inspected by N. Davis
A3: PL-002 | B3: Field | C3: Electrical | D3: Paint touch-up required on south wall | E3: Critical | F3: L. Chen | G3: 46145 | H3: 46158 | I3: =IF(G3="","",TODAY()-G3) | J3: Open
A4: PL-003 | B4: Storage | C4: Carpentry | D4: Thermostat not communicating with BMS | E4: Low | F4: J. Garcia | G4: 46139 | H4: 46159 | I4: =IF(G4="","",TODAY()-G4) | J4: Ready for Review
A5: PL-004 | B5: Exterior | C5: Painting | D5: Toilet flange not secured to floor | E5: Low | F5: R. Thompson | G5: 46158 | H5: 46181 | I5: =IF(G5="","",TODAY()-G5) | J5: Rejected | K5: Inspected by A. Kim
A6: PL-005 | B6: Restroom | C6: Steel | D6: Ceiling tile stained — replace | E6: High | F6: K. Johnson | G6: 46161 | H6: 46191 | I6: =IF(G6="","",TODAY()-G6) | J6: Closed | K6: Inspected by L. Chen
A7: PL-006 | B7: Restroom | C7: HVAC | D7: Sprinkler head paint overspray — clean | E7: High | F7: L. Chen | G7: 46040 | H7: 46067 | I7: =IF(G7="","",TODAY()-G7) | J7: Closed | K7: Inspected by N. Davis
A8: PL-007 | B8: Lobby | C8: Millwork | D8: GFCI outlet missing cover plate | E8: Medium | F8: R. Thompson | G8: 46136 | H8: 46158 | I8: =IF(G8="","",TODAY()-G8) | J8: Closed
A9: PL-008 | B9: Field | C9: Steel | D9: Light fixture not aligned with grid | E9: Critical | F9: D. Williams | G9: 46140 | H9: 46163 | I9: =IF(G9="","",TODAY()-G9) | J9: Closed
A10: PL-009 | B10: Exterior | C10: MEP | D10: Missing fire caulking at pipe penetration | E10: Low | F10: T. Brown | G10: 46074 | H10: 46086 | I10: =IF(G10="","",TODAY()-G10) | J10: Open
A11: PL-010 | B11: Lobby | C11: Painting | D11: Window seal gap — apply silicone | E11: Critical | F11: A. Kim | G11: 46042 | H11: 46062 | I11: =IF(G11="","",TODAY()-G11) | J11: In Progress
A12: PL-011 | B12: Lobby | C12: Millwork | D12: Drain cleanout plug cross-threaded | E12: High | F12: T. Brown | G12: 46135 | H12: 46142 | I12: =IF(G12="","",TODAY()-G12) | J12: Open
A13: PL-012 | B13: Concourse | C13: Millwork | D13: Screw pops in drywall — repair and finish | E13: Low | F13: J. Garcia | G13: 46093 | H13: 46119 | I13: =IF(G13="","",TODAY()-G13) | J13: Ready for Review | K13: Inspected by R. Thompson
A14: PL-013 | B14: Lobby | C14: MEP | D14: Handrail bracket loose on stairway | E14: Critical | F14: R. Thompson | G14: 46090 | H14: 46097 | I14: =IF(G14="","",TODAY()-G14) | J14: Open
A15: PL-014 | B15: Roof | C15: Steel | D15: Mirror damaged in west restroom | E15: High | F15: N. Davis | G15: 46146 | H15: 46163 | I15: =IF(G15="","",TODAY()-G15) | J15: In Progress
A16: PL-015 | B16: Field | C16: Carpentry | D16: Floor tile cracked — replace 12×12 section | E16: Medium | F16: J. Garcia | G16: 46174 | H16: 46204 | I16: =IF(G16="","",TODAY()-G16) | J16: Open
A17: PL-016 | B17: Stairwell | C17: Plumbing | D17: Drain cleanout plug cross-threaded | E17: Medium | F17: T. Brown | G17: 46065 | H17: 46074 | I17: =IF(G17="","",TODAY()-G17) | J17: Closed
A18: PL-017 | B18: Concourse | C18: Millwork | D18: Drain cleanout plug cross-threaded | E18: Medium | F18: R. Thompson | G18: 46048 | H18: 46057 | I18: =IF(G18="","",TODAY()-G18) | J18: Ready for Review
A19: PL-018 | B19: Field | C19: Flooring | D19: Paint touch-up required on south wall | E19: Medium | F19: K. Johnson | G19: 46058 | H19: 46070 | I19: =IF(G19="","",TODAY()-G19) | J19: In Progress
A20: PL-019 | B20: Lobby | C20: Millwork | D20: Crack in concrete slab near column B-12 | E20: Critical | F20: T. Brown | G20: 46149 | H20: 46164 | I20: =IF(G20="","",TODAY()-G20) | J20: In Progress | K20: Inspected by S. Rodriguez
A21: PL-020 | B21: Exterior | C21: Glass/Glazing | D21: Fire damper actuator not tested | E21: Critical | F21: N. Davis | G21: 46046 | H21: 46058 | I21: =IF(G21="","",TODAY()-G21) | J21: Ready for Review | K21: Inspected by M. Patel
A22: PL-021 | B22: Exterior | C22: Carpentry | D22: Signage panel not level | E22: Low | F22: S. Rodriguez | G22: 46039 | H22: 46048 | I22: =IF(G22="","",TODAY()-G22) | J22: In Progress
A23: PL-022 | B23: Concourse | C23: Concrete | D23: Sprinkler head paint overspray — clean | E23: Low | F23: M. Patel | G23: 46176 | H23: 46185 | I23: =IF(G23="","",TODAY()-G23) | J23: Closed
A24: PL-023 | B24: Restroom | C24: Carpentry | D24: Handrail bracket loose on stairway | E24: High | F24: K. Johnson | G24: 46077 | H24: 46091 | I24: =IF(G24="","",TODAY()-G24) | J24: Ready for Review
A25: PL-024 | B25: Concourse | C25: Concrete | D25: Sprinkler head paint overspray — clean | E25: High | F25: N. Davis | G25: 46059 | H25: 46075 | I25: =IF(G25="","",TODAY()-G25) | J25: Open
A26: PL-025 | B26: Stairwell | C26: Glass/Glazing | D26: Caulking missing at countertop backsplash | E26: Low | F26: S. Rodriguez | G26: 46147 | H26: 46177 | I26: =IF(G26="","",TODAY()-G26) | J26: Closed
A27: PL-026 | B27: Concourse | C27: MEP | D27: Millwork edge banding peeling on cabinet | E27: Low | F27: K. Johnson | G27: 46118 | H27: 46131 | I27: =IF(G27="","",TODAY()-G27) | J27: Open
A28: PL-027 | B28: Restroom | C28: Painting | D28: ADA push plate missing on exit door | E28: Critical | F28: N. Davis | G28: 46130 | H28: 46147 | I28: =IF(G28="","",TODAY()-G28) | J28: Open | K28: Inspected by T. Brown
A29: PL-028 | B29: Field | C29: Millwork | D29: Roof membrane patched — verify watertight | E29: Low | F29: K. Johnson | G29: 46167 | H29: 46179 | I29: =IF(G29="","",TODAY()-G29) | J29: Closed | K29: Inspected by K. Johnson
A30: PL-029 | B30: MEP Room | C30: Carpentry | D30: Expansion joint cover loose | E30: High | F30: L. Chen | G30: 46088 | H30: 46114 | I30: =IF(G30="","",TODAY()-G30) | J30: Closed
A31: PL-030 | B31: Suite | C31: Plumbing | D31: Crack in concrete slab near column B-12 | E31: Medium | F31: R. Thompson | G31: 46157 | H31: 46167 | I31: =IF(G31="","",TODAY()-G31) | J31: Open | K31: Inspected by R. Thompson
A32: PL-031 | B32: Concourse | C32: General | D32: Screw pops in drywall — repair and finish | E32: Critical | F32: D. Williams | G32: 46167 | H32: 46183 | I32: =IF(G32="","",TODAY()-G32) | J32: Rejected | K32: Inspected by R. Thompson
A33: PL-032 | B33: Roof | C33: Finish | D33: Screw pops in drywall — repair and finish | E33: Critical | F33: N. Davis | G33: 46044 | H33: 46059 | I33: =IF(G33="","",TODAY()-G33) | J33: Open
A34: PL-033 | B34: Restroom | C34: Flooring | D34: Corner guard adhesive failing | E34: Medium | F34: T. Brown | G34: 46172 | H34: 46198 | I34: =IF(G34="","",TODAY()-G34) | J34: Closed | K34: Inspected by A. Kim
A35: PL-034 | B35: Lobby | C35: Steel | D35: Fire damper actuator not tested | E35: Low | F35: K. Johnson | G35: 46109 | H35: 46136 | I35: =IF(G35="","",TODAY()-G35) | J35: Ready for Review
A36: PL-035 | B36: Exterior | C36: Glass/Glazing | D36: Toilet flange not secured to floor | E36: Critical | F36: K. Johnson | G36: 46169 | H36: 46183 | I36: =IF(G36="","",TODAY()-G36) | J36: In Progress | K36: Inspected by R. Thompson
A37: PL-036 | B37: Suite | C37: Flooring | D37: Corner guard adhesive failing | E37: Low | F37: D. Williams | G37: 46166 | H37: 46196 | I37: =IF(G37="","",TODAY()-G37) | J37: Ready for Review | K37: Inspected by K. Johnson
A38: PL-037 | B38: Field | C38: Carpentry | D38: Floor tile cracked — replace 12×12 section | E38: Critical | F38: D. Williams | G38: 46102 | H38: 46125 | I38: =IF(G38="","",TODAY()-G38) | J38: Open
A39: PL-038 | B39: Restroom | C39: HVAC | D39: Screw pops in drywall — repair and finish | E39: Low | F39: S. Rodriguez | G39: 46126 | H39: 46140 | I39: =IF(G39="","",TODAY()-G39) | J39: Open | K39: Inspected by T. Brown
A40: PL-039 | B40: Lobby | C40: MEP | D40: Sprinkler head paint overspray — clean | E40: Low | F40: R. Thompson | G40: 46045 | H40: 46071 | I40: =IF(G40="","",TODAY()-G40) | J40: Closed
...

Sheet Summary
A1: PUNCH LIST SUMMARY REPORT
A3: Total Items | B3: =COUNTA('Punch List'!A2:A201)
A5: STATUS BREAKDOWN
A6: Open | B6: =COUNTIF('Punch List'!J2:J201,"Open") | C6: =IF(COUNTA('Punch List'!A2:A201)=0,0,=COUNTIF('Punch List'!J2:J201,"Open")/COUNTA('Punch List'!A2:A201))
A7: In Progress | B7: =COUNTIF('Punch List'!J2:J201,"In Progress") | C7: =IF(COUNTA('Punch List'!A2:A201)=0,0,=COUNTIF('Punch List'!J2:J201,"In Progress")/COUNTA('Punch List'!A2:A201))
A8: Ready for Review | B8: =COUNTIF('Punch List'!J2:J201,"Ready for Review") | C8: =IF(COUNTA('Punch List'!A2:A201)=0,0,=COUNTIF('Punch List'!J2:J201,"Ready for Review")/COUNTA('Punch List'!A2:A201))
A9: Closed | B9: =COUNTIF('Punch List'!J2:J201,"Closed") | C9: =IF(COUNTA('Punch List'!A2:A201)=0,0,=COUNTIF('Punch List'!J2:J201,"Closed")/COUNTA('Punch List'!A2:A201))
A10: Rejected | B10: =COUNTIF('Punch List'!J2:J201,"Rejected") | C10: =IF(COUNTA('Punch List'!A2:A201)=0,0,=COUNTIF('Punch List'!J2:J201,"Rejected")/COUNTA('Punch List'!A2:A201))
A12: BY PRIORITY
A13: Low | B13: =COUNTIF('Punch List'!E2:E201,"Low")
A14: Medium | B14: =COUNTIF('Punch List'!E2:E201,"Medium")
A15: High | B15: =COUNTIF('Punch List'!E2:E201,"High")
A16: Critical | B16: =COUNTIF('Punch List'!E2:E201,"Critical")
A18: TOP TRADES
A19: Concrete | B19: =COUNTIF('Punch List'!C2:C201,"Concrete")
A20: Steel | B20: =COUNTIF('Punch List'!C2:C201,"Steel")
A21: MEP | B21: =COUNTIF('Punch List'!C2:C201,"MEP")
A22: Finish | B22: =COUNTIF('Punch List'!C2:C201,"Finish")
A23: Electrical | B23: =COUNTIF('Punch List'!C2:C201,"Electrical")
A24: Plumbing | B24: =COUNTIF('Punch List'!C2:C201,"Plumbing")
A25: HVAC | B25: =COUNTIF('Punch List'!C2:C201,"HVAC")
A26: Carpentry | B26: =COUNTIF('Punch List'!C2:C201,"Carpentry")
A27: Painting | B27: =COUNTIF('Punch List'!C2:C201,"Painting")
A28: Flooring | B28: =COUNTIF('Punch List'!C2:C201,"Flooring")
A30: AVERAGE DAYS OPEN
A31: Avg Days Open (Open Items) | B31: =IFERROR(AVERAGEIF('Punch List'!J2:J201,"Open",'Punch List'!I2:I201),0)
A32: Avg Days Open (All Items) | B32: =IFERROR(AVERAGE('Punch List'!I2:I201),0)
